Workbook

Sheet 月度计算
A1: 连续劳务报酬 12个月计算器（按上传规则）
A2: 用法：每月二选一输入（含税或实发），系统自动计算另一项；若中间月份无收入，下月自动重新按第1个月累计。
A4: 月份 | B4: 输入含税金额 | C4: 输入实发金额 | D4: 是否有收入 | E4: 连续月数 | F4: 累计已预扣个税(本月计算用) | G4: 含税金额(结果) | H4: 不含税金额 | I4: 增值税 | J4: 城建税 | K4: 教育附加税 | L4: 地方教育附加税 | M4: 当月收入(含税-增值税) | N4: 累计应纳所得额 | O4: 预扣率 | P4: 速算扣除数 | Q4: 本月个税 | R4: 税额合计 | S4: 实发金额(结果) | T4: 本连续段个税合计 | U4: 误差/提示 | V4: 备注 | W4: 当月附加合计 | X4: 本连续段累计含税 | Y4: 本连续段累计增值税 | Z4: 本连续段累计附加 | AA4: 本连续段累计收入 | AB4: 上月累计收入 | AC4: 上月累计附加
A5: 1 | B5: 51797.23 | D5: =IF(OR(B5<>"",C5<>""),1,0) | E5: =IF(D5=0,0,1) | F5: =IF(D5=0,"",0) | G5: =IF(D5=0,"",IF(B5<>"",B5,IFERROR(INDEX(反算辅助!$DC$2:$DC$13,ROW()-4),""))) | H5: =IF(ISNUMBER(G5),G5/(1+IF(G5<100000,0,1%)),"") | I5: =IF(ISNUMBER(G5),IF(H5<100000,0,H5*1%),"") | J5: =IF(ISNUMBER(G5),IF(H5<100000,0,I5*2.5%),"") | K5: =IF(ISNUMBER(G5),IF(H5<100000,0,I5*1.5%),"") | L5: =IF(ISNUMBER(G5),IF(H5<100000,0,I5*1%),"") | M5: =IF(ISNUMBER(G5),G5-I5,"") | N5: =IF(D5=0,"",AA5*80%-5000*E5-Z5) | O5: =IF(D5=0,"",IF(N5<=36000,3%,IF(N5<=144000,10%,IF(N5<=300000,20%,IF(N5<=420000,25%,IF(N5<=660000,30%,IF(N5<=960000,35%,45%))))))) | P5: =IF(D5=0,"",IF(N5<=36000,0,IF(N5<=144000,2520,IF(N5<=300000,16920,IF(N5<=420000,31920,IF(N5<=660000,52920,IF(N5<=960000,85920,181920))))))) | Q5: =IF(D5=0,"",MAX(0,N5*O5-P5-F5)) | R5: =IF(D5=0,"",I5+J5+K5+L5+Q5) | S5: =IF(D5=0,"",G5-R5) | T5: =IF(D5=0,"",F5+Q5) | U5: =IF(AND(C5<>"",B5=""),S5-C5,"") | V5: =IF(AND(D5=1,ISNUMBER(G5)=FALSE),"反算失败，请检查输入",IF(AND(B5<>"",C5<>""),"已按含税金额优先","")) | W5: =IF(ISNUMBER(G5),J5+K5+L5,"") | X5: =IF(D5=0,"",G5) | Y5: =IF(D5=0,"",I5) | Z5: =IF(D5=0,"",W5) | AA5: =IF(D5=0,"",X5-Y5) | AB5: =IF(D5=0,"",0) | AC5: =IF(D5=0,"",0)
A6: 2 | D6: =IF(OR(B6<>"",C6<>""),1,0) | E6: =IF(D6=0,0,IF(D5=0,1,E5+1)) | F6: =IF(D6=0,"",IF(D5=0,0,T5)) | G6: =IF(D6=0,"",IF(B6<>"",B6,IFERROR(INDEX(反算辅助!$DC$2:$DC$13,ROW()-4),""))) | H6: =IF(ISNUMBER(G6),G6/(1+IF(G6<100000,0,1%)),"") | I6: =IF(ISNUMBER(G6),IF(H6<100000,0,H6*1%),"") | J6: =IF(ISNUMBER(G6),IF(H6<100000,0,I6*2.5%),"") | K6: =IF(ISNUMBER(G6),IF(H6<100000,0,I6*1.5%),"") | L6: =IF(ISNUMBER(G6),IF(H6<100000,0,I6*1%),"") | M6: =IF(ISNUMBER(G6),G6-I6,"") | N6: =IF(D6=0,"",AA6*80%-5000*E6-Z6) | O6: =IF(D6=0,"",IF(N6<=36000,3%,IF(N6<=144000,10%,IF(N6<=300000,20%,IF(N6<=420000,25%,IF(N6<=660000,30%,IF(N6<=960000,35%,45%))))))) | P6: =IF(D6=0,"",IF(N6<=36000,0,IF(N6<=144000,2520,IF(N6<=300000,16920,IF(N6<=420000,31920,IF(N6<=660000,52920,IF(N6<=960000,85920,181920))))))) | Q6: =IF(D6=0,"",MAX(0,N6*O6-P6-F6)) | R6: =IF(D6=0,"",I6+J6+K6+L6+Q6) | S6: =IF(D6=0,"",G6-R6) | T6: =IF(D6=0,"",F6+Q6) | U6: =IF(AND(C6<>"",B6=""),S6-C6,"") | V6: =IF(AND(D6=1,ISNUMBER(G6)=FALSE),"反算失败，请检查输入",IF(AND(B6<>"",C6<>""),"已按含税金额优先","")) | W6: =IF(ISNUMBER(G6),J6+K6+L6,"") | X6: =IF(D6=0,"",IF(D5=0,G6,X5+G6)) | Y6: =IF(D6=0,"",IF(D5=0,I6,Y5+I6)) | Z6: =IF(D6=0,"",IF(D5=0,W6,Z5+W6)) | AA6: =IF(D6=0,"",X6-Y6) | AB6: =IF(D6=0,"",IF(D5=0,0,AA5)) | AC6: =IF(D6=0,"",IF(D5=0,0,Z5))
A7: 3 | D7: =IF(OR(B7<>"",C7<>""),1,0) | E7: =IF(D7=0,0,IF(D6=0,1,E6+1)) | F7: =IF(D7=0,"",IF(D6=0,0,T6)) | G7: =IF(D7=0,"",IF(B7<>"",B7,IFERROR(INDEX(反算辅助!$DC$2:$DC$13,ROW()-4),""))) | H7: =IF(ISNUMBER(G7),G7/(1+IF(G7<100000,0,1%)),"") | I7: =IF(ISNUMBER(G7),IF(H7<100000,0,H7*1%),"") | J7: =IF(ISNUMBER(G7),IF(H7<100000,0,I7*2.5%),"") | K7: =IF(ISNUMBER(G7),IF(H7<100000,0,I7*1.5%),"") | L7: =IF(ISNUMBER(G7),IF(H7<100000,0,I7*1%),"") | M7: =IF(ISNUMBER(G7),G7-I7,"") | N7: =IF(D7=0,"",AA7*80%-5000*E7-Z7) | O7: =IF(D7=0,"",IF(N7<=36000,3%,IF(N7<=144000,10%,IF(N7<=300000,20%,IF(N7<=420000,25%,IF(N7<=660000,30%,IF(N7<=960000,35%,45%))))))) | P7: =IF(D7=0,"",IF(N7<=36000,0,IF(N7<=144000,2520,IF(N7<=300000,16920,IF(N7<=420000,31920,IF(N7<=660000,52920,IF(N7<=960000,85920,181920))))))) | Q7: =IF(D7=0,"",MAX(0,N7*O7-P7-F7)) | R7: =IF(D7=0,"",I7+J7+K7+L7+Q7) | S7: =IF(D7=0,"",G7-R7) | T7: =IF(D7=0,"",F7+Q7) | U7: =IF(AND(C7<>"",B7=""),S7-C7,"") | V7: =IF(AND(D7=1,ISNUMBER(G7)=FALSE),"反算失败，请检查输入",IF(AND(B7<>"",C7<>""),"已按含税金额优先","")) | W7: =IF(ISNUMBER(G7),J7+K7+L7,"") | X7: =IF(D7=0,"",IF(D6=0,G7,X6+G7)) | Y7: =IF(D7=0,"",IF(D6=0,I7,Y6+I7)) | Z7: =IF(D7=0,"",IF(D6=0,W7,Z6+W7)) | AA7: =IF(D7=0,"",X7-Y7) | AB7: =IF(D7=0,"",IF(D6=0,0,AA6)) | AC7: =IF(D7=0,"",IF(D6=0,0,Z6))
A8: 4 | D8: =IF(OR(B8<>"",C8<>""),1,0) | E8: =IF(D8=0,0,IF(D7=0,1,E7+1)) | F8: =IF(D8=0,"",IF(D7=0,0,T7)) | G8: =IF(D8=0,"",IF(B8<>"",B8,IFERROR(INDEX(反算辅助!$DC$2:$DC$13,ROW()-4),""))) | H8: =IF(ISNUMBER(G8),G8/(1+IF(G8<100000,0,1%)),"") | I8: =IF(ISNUMBER(G8),IF(H8<100000,0,H8*1%),"") | J8: =IF(ISNUMBER(G8),IF(H8<100000,0,I8*2.5%),"") | K8: =IF(ISNUMBER(G8),IF(H8<100000,0,I8*1.5%),"") | L8: =IF(ISNUMBER(G8),IF(H8<100000,0,I8*1%),"") | M8: =IF(ISNUMBER(G8),G8-I8,"") | N8: =IF(D8=0,"",AA8*80%-5000*E8-Z8) | O8: =IF(D8=0,"",IF(N8<=36000,3%,IF(N8<=144000,10%,IF(N8<=300000,20%,IF(N8<=420000,25%,IF(N8<=660000,30%,IF(N8<=960000,35%,45%))))))) | P8: =IF(D8=0,"",IF(N8<=36000,0,IF(N8<=144000,2520,IF(N8<=300000,16920,IF(N8<=420000,31920,IF(N8<=660000,52920,IF(N8<=960000,85920,181920))))))) | Q8: =IF(D8=0,"",MAX(0,N8*O8-P8-F8)) | R8: =IF(D8=0,"",I8+J8+K8+L8+Q8) | S8: =IF(D8=0,"",G8-R8) | T8: =IF(D8=0,"",F8+Q8) | U8: =IF(AND(C8<>"",B8=""),S8-C8,"") | V8: =IF(AND(D8=1,ISNUMBER(G8)=FALSE),"反算失败，请检查输入",IF(AND(B8<>"",C8<>""),"已按含税金额优先","")) | W8: =IF(ISNUMBER(G8),J8+K8+L8,"") | X8: =IF(D8=0,"",IF(D7=0,G8,X7+G8)) | Y8: =IF(D8=0,"",IF(D7=0,I8,Y7+I8)) | Z8: =IF(D8=0,"",IF(D7=0,W8,Z7+W8)) | AA8: =IF(D8=0,"",X8-Y8) | AB8: =IF(D8=0,"",IF(D7=0,0,AA7)) | AC8: =IF(D8=0,"",IF(D7=0,0,Z7))
A9: 5 | D9: =IF(OR(B9<>"",C9<>""),1,0) | E9: =IF(D9=0,0,IF(D8=0,1,E8+1)) | F9: =IF(D9=0,"",IF(D8=0,0,T8)) | G9: =IF(D9=0,"",IF(B9<>"",B9,IFERROR(INDEX(反算辅助!$DC$2:$DC$13,ROW()-4),""))) | H9: =IF(ISNUMBER(G9),G9/(1+IF(G9<100000,0,1%)),"") | I9: =IF(ISNUMBER(G9),IF(H9<100000,0,H9*1%),"") | J9: =IF(ISNUMBER(G9),IF(H9<100000,0,I9*2.5%),"") | K9: =IF(ISNUMBER(G9),IF(H9<100000,0,I9*1.5%),"") | L9: =IF(ISNUMBER(G9),IF(H9<100000,0,I9*1%),"") | M9: =IF(ISNUMBER(G9),G9-I9,"") | N9: =IF(D9=0,"",AA9*80%-5000*E9-Z9) | O9: =IF(D9=0,"",IF(N9<=36000,3%,IF(N9<=144000,10%,IF(N9<=300000,20%,IF(N9<=420000,25%,IF(N9<=660000,30%,IF(N9<=960000,35%,45%))))))) | P9: =IF(D9=0,"",IF(N9<=36000,0,IF(N9<=144000,2520,IF(N9<=300000,16920,IF(N9<=420000,31920,IF(N9<=660000,52920,IF(N9<=960000,85920,181920))))))) | Q9: =IF(D9=0,"",MAX(0,N9*O9-P9-F9)) | R9: =IF(D9=0,"",I9+J9+K9+L9+Q9) | S9: =IF(D9=0,"",G9-R9) | T9: =IF(D9=0,"",F9+Q9) | U9: =IF(AND(C9<>"",B9=""),S9-C9,"") | V9: =IF(AND(D9=1,ISNUMBER(G9)=FALSE),"反算失败，请检查输入",IF(AND(B9<>"",C9<>""),"已按含税金额优先","")) | W9: =IF(ISNUMBER(G9),J9+K9+L9,"") | X9: =IF(D9=0,"",IF(D8=0,G9,X8+G9)) | Y9: =IF(D9=0,"",IF(D8=0,I9,Y8+I9)) | Z9: =IF(D9=0,"",IF(D8=0,W9,Z8+W9)) | AA9: =IF(D9=0,"",X9-Y9) | AB9: =IF(D9=0,"",IF(D8=0,0,AA8)) | AC9: =IF(D9=0,"",IF(D8=0,0,Z8))
A10: 6 | D10: =IF(OR(B10<>"",C10<>""),1,0) | E10: =IF(D10=0,0,IF(D9=0,1,E9+1)) | F10: =IF(D10=0,"",IF(D9=0,0,T9)) | G10: =IF(D10=0,"",IF(B10<>"",B10,IFERROR(INDEX(反算辅助!$DC$2:$DC$13,ROW()-4),""))) | H10: =IF(ISNUMBER(G10),G10/(1+IF(G10<100000,0,1%)),"") | I10: =IF(ISNUMBER(G10),IF(H10<100000,0,H10*1%),"") | J10: =IF(ISNUMBER(G10),IF(H10<100000,0,I10*2.5%),"") | K10: =IF(ISNUMBER(G10),IF(H10<100000,0,I10*1.5%),"") | L10: =IF(ISNUMBER(G10),IF(H10<100000,0,I10*1%),"") | M10: =IF(ISNUMBER(G10),G10-I10,"") | N10: =IF(D10=0,"",AA10*80%-5000*E10-Z10) | O10: =IF(D10=0,"",IF(N10<=36000,3%,IF(N10<=144000,10%,IF(N10<=300000,20%,IF(N10<=420000,25%,IF(N10<=660000,30%,IF(N10<=960000,35%,45%))))))) | P10: =IF(D10=0,"",IF(N10<=36000,0,IF(N10<=144000,2520,IF(N10<=300000,16920,IF(N10<=420000,31920,IF(N10<=660000,52920,IF(N10<=960000,85920,181920))))))) | Q10: =IF(D10=0,"",MAX(0,N10*O10-P10-F10)) | R10: =IF(D10=0,"",I10+J10+K10+L10+Q10) | S10: =IF(D10=0,"",G10-R10) | T10: =IF(D10=0,"",F10+Q10) | U10: =IF(AND(C10<>"",B10=""),S10-C10,"") | V10: =IF(AND(D10=1,ISNUMBER(G10)=FALSE),"反算失败，请检查输入",IF(AND(B10<>"",C10<>""),"已按含税金额优先","")) | W10: =IF(ISNUMBER(G10),J10+K10+L10,"") | X10: =IF(D10=0,"",IF(D9=0,G10,X9+G10)) | Y10: =IF(D10=0,"",IF(D9=0,I10,Y9+I10)) | Z10: =IF(D10=0,"",IF(D9=0,W10,Z9+W10)) | AA10: =IF(D10=0,"",X10-Y10) | AB10: =IF(D10=0,"",IF(D9=0,0,AA9)) | AC10: =IF(D10=0,"",IF(D9=0,0,Z9))
A11: 7 | D11: =IF(OR(B11<>"",C11<>""),1,0) | E11: =IF(D11=0,0,IF(D10=0,1,E10+1)) | F11: =IF(D11=0,"",IF(D10=0,0,T10)) | G11: =IF(D11=0,"",IF(B11<>"",B11,IFERROR(INDEX(反算辅助!$DC$2:$DC$13,ROW()-4),""))) | H11: =IF(ISNUMBER(G11),G11/(1+IF(G11<100000,0,1%)),"") | I11: =IF(ISNUMBER(G11),IF(H11<100000,0,H11*1%),"") | J11: =IF(ISNUMBER(G11),IF(H11<100000,0,I11*2.5%),"") | K11: =IF(ISNUMBER(G11),IF(H11<100000,0,I11*1.5%),"") | L11: =IF(ISNUMBER(G11),IF(H11<100000,0,I11*1%),"") | M11: =IF(ISNUMBER(G11),G11-I11,"") | N11: =IF(D11=0,"",AA11*80%-5000*E11-Z11) | O11: =IF(D11=0,"",IF(N11<=36000,3%,IF(N11<=144000,10%,IF(N11<=300000,20%,IF(N11<=420000,25%,IF(N11<=660000,30%,IF(N11<=960000,35%,45%))))))) | P11: =IF(D11=0,"",IF(N11<=36000,0,IF(N11<=144000,2520,IF(N11<=300000,16920,IF(N11<=420000,31920,IF(N11<=660000,52920,IF(N11<=960000,85920,181920))))))) | Q11: =IF(D11=0,"",MAX(0,N11*O11-P11-F11)) | R11: =IF(D11=0,"",I11+J11+K11+L11+Q11) | S11: =IF(D11=0,"",G11-R11) | T11: =IF(D11=0,"",F11+Q11) | U11: =IF(AND(C11<>"",B11=""),S11-C11,"") | V11: =IF(AND(D11=1,ISNUMBER(G11)=FALSE),"反算失败，请检查输入",IF(AND(B11<>"",C11<>""),"已按含税金额优先","")) | W11: =IF(ISNUMBER(G11),J11+K11+L11,"") | X11: =IF(D11=0,"",IF(D10=0,G11,X10+G11)) | Y11: =IF(D11=0,"",IF(D10=0,I11,Y10+I11)) | Z11: =IF(D11=0,"",IF(D10=0,W11,Z10+W11)) | AA11: =IF(D11=0,"",X11-Y11) | AB11: =IF(D11=0,"",IF(D10=0,0,AA10)) | AC11: =IF(D11=0,"",IF(D10=0,0,Z10))
A12: 8 | D12: =IF(OR(B12<>"",C12<>""),1,0) | E12: =IF(D12=0,0,IF(D11=0,1,E11+1)) | F12: =IF(D12=0,"",IF(D11=0,0,T11)) | G12: =IF(D12=0,"",IF(B12<>"",B12,IFERROR(INDEX(反算辅助!$DC$2:$DC$13,ROW()-4),""))) | H12: =IF(ISNUMBER(G12),G12/(1+IF(G12<100000,0,1%)),"") | I12: =IF(ISNUMBER(G12),IF(H12<100000,0,H12*1%),"") | J12: =IF(ISNUMBER(G12),IF(H12<100000,0,I12*2.5%),"") | K12: =IF(ISNUMBER(G12),IF(H12<100000,0,I12*1.5%),"") | L12: =IF(ISNUMBER(G12),IF(H12<100000,0,I12*1%),"") | M12: =IF(ISNUMBER(G12),G12-I12,"") | N12: =IF(D12=0,"",AA12*80%-5000*E12-Z12) | O12: =IF(D12=0,"",IF(N12<=36000,3%,IF(N12<=144000,10%,IF(N12<=300000,20%,IF(N12<=420000,25%,IF(N12<=660000,30%,IF(N12<=960000,35%,45%))))))) | P12: =IF(D12=0,"",IF(N12<=36000,0,IF(N12<=144000,2520,IF(N12<=300000,16920,IF(N12<=420000,31920,IF(N12<=660000,52920,IF(N12<=960000,85920,181920))))))) | Q12: =IF(D12=0,"",MAX(0,N12*O12-P12-F12)) | R12: =IF(D12=0,"",I12+J12+K12+L12+Q12) | S12: =IF(D12=0,"",G12-R12) | T12: =IF(D12=0,"",F12+Q12) | U12: =IF(AND(C12<>"",B12=""),S12-C12,"") | V12: =IF(AND(D12=1,ISNUMBER(G12)=FALSE),"反算失败，请检查输入",IF(AND(B12<>"",C12<>""),"已按含税金额优先","")) | W12: =IF(ISNUMBER(G12),J12+K12+L12,"") | X12: =IF(D12=0,"",IF(D11=0,G12,X11+G12)) | Y12: =IF(D12=0,"",IF(D11=0,I12,Y11+I12)) | Z12: =IF(D12=0,"",IF(D11=0,W12,Z11+W12)) | AA12: =IF(D12=0,"",X12-Y12) | AB12: =IF(D12=0,"",IF(D11=0,0,AA11)) | AC12: =IF(D12=0,"",IF(D11=0,0,Z11))
A13: 9 | D13: =IF(OR(B13<>"",C13<>""),1,0) | E13: =IF(D13=0,0,IF(D12=0,1,E12+1)) | F13: =IF(D13=0,"",IF(D12=0,0,T12)) | G13: =IF(D13=0,"",IF(B13<>"",B13,IFERROR(INDEX(反算辅助!$DC$2:$DC$13,ROW()-4),""))) | H13: =IF(ISNUMBER(G13),G13/(1+IF(G13<100000,0,1%)),"") | I13: =IF(ISNUMBER(G13),IF(H13<100000,0,H13*1%),"") | J13: =IF(ISNUMBER(G13),IF(H13<100000,0,I13*2.5%),"") | K13: =IF(ISNUMBER(G13),IF(H13<100000,0,I13*1.5%),"") | L13: =IF(ISNUMBER(G13),IF(H13<100000,0,I13*1%),"") | M13: =IF(ISNUMBER(G13),G13-I13,"") | N13: =IF(D13=0,"",AA13*80%-5000*E13-Z13) | O13: =IF(D13=0,"",IF(N13<=36000,3%,IF(N13<=144000,10%,IF(N13<=300000,20%,IF(N13<=420000,25%,IF(N13<=660000,30%,IF(N13<=960000,35%,45%))))))) | P13: =IF(D13=0,"",IF(N13<=36000,0,IF(N13<=144000,2520,IF(N13<=300000,16920,IF(N13<=420000,31920,IF(N13<=660000,52920,IF(N13<=960000,85920,181920))))))) | Q13: =IF(D13=0,"",MAX(0,N13*O13-P13-F13)) | R13: =IF(D13=0,"",I13+J13+K13+L13+Q13) | S13: =IF(D13=0,"",G13-R13) | T13: =IF(D13=0,"",F13+Q13) | U13: =IF(AND(C13<>"",B13=""),S13-C13,"") | V13: =IF(AND(D13=1,ISNUMBER(G13)=FALSE),"反算失败，请检查输入",IF(AND(B13<>"",C13<>""),"已按含税金额优先","")) | W13: =IF(ISNUMBER(G13),J13+K13+L13,"") | X13: =IF(D13=0,"",IF(D12=0,G13,X12+G13)) | Y13: =IF(D13=0,"",IF(D12=0,I13,Y12+I13)) | Z13: =IF(D13=0,"",IF(D12=0,W13,Z12+W13)) | AA13: =IF(D13=0,"",X13-Y13) | AB13: =IF(D13=0,"",IF(D12=0,0,AA12)) | AC13: =IF(D13=0,"",IF(D12=0,0,Z12))
A14: 10 | D14: =IF(OR(B14<>"",C14<>""),1,0) | E14: =IF(D14=0,0,IF(D13=0,1,E13+1)) | F14: =IF(D14=0,"",IF(D13=0,0,T13)) | G14: =IF(D14=0,"",IF(B14<>"",B14,IFERROR(INDEX(反算辅助!$DC$2:$DC$13,ROW()-4),""))) | H14: =IF(ISNUMBER(G14),G14/(1+IF(G14<100000,0,1%)),"") | I14: =IF(ISNUMBER(G14),IF(H14<100000,0,H14*1%),"") | J14: =IF(ISNUMBER(G14),IF(H14<100000,0,I14*2.5%),"") | K14: =IF(ISNUMBER(G14),IF(H14<100000,0,I14*1.5%),"") | L14: =IF(ISNUMBER(G14),IF(H14<100000,0,I14*1%),"") | M14: =IF(ISNUMBER(G14),G14-I14,"") | N14: =IF(D14=0,"",AA14*80%-5000*E14-Z14) | O14: =IF(D14=0,"",IF(N14<=36000,3%,IF(N14<=144000,10%,IF(N14<=300000,20%,IF(N14<=420000,25%,IF(N14<=660000,30%,IF(N14<=960000,35%,45%))))))) | P14: =IF(D14=0,"",IF(N14<=36000,0,IF(N14<=144000,2520,IF(N14<=300000,16920,IF(N14<=420000,31920,IF(N14<=660000,52920,IF(N14<=960000,85920,181920))))))) | Q14: =IF(D14=0,"",MAX(0,N14*O14-P14-F14)) | R14: =IF(D14=0,"",I14+J14+K14+L14+Q14) | S14: =IF(D14=0,"",G14-R14) | T14: =IF(D14=0,"",F14+Q14) | U14: =IF(AND(C14<>"",B14=""),S14-C14,"") | V14: =IF(AND(D14=1,ISNUMBER(G14)=FALSE),"反算失败，请检查输入",IF(AND(B14<>"",C14<>""),"已按含税金额优先","")) | W14: =IF(ISNUMBER(G14),J14+K14+L14,"") | X14: =IF(D14=0,"",IF(D13=0,G14,X13+G14)) | Y14: =IF(D14=0,"",IF(D13=0,I14,Y13+I14)) | Z14: =IF(D14=0,"",IF(D13=0,W14,Z13+W14)) | AA14: =IF(D14=0,"",X14-Y14) | AB14: =IF(D14=0,"",IF(D13=0,0,AA13)) | AC14: =IF(D14=0,"",IF(D13=0,0,Z13))
A15: 11 | D15: =IF(OR(B15<>"",C15<>""),1,0) | E15: =IF(D15=0,0,IF(D14=0,1,E14+1)) | F15: =IF(D15=0,"",IF(D14=0,0,T14)) | G15: =IF(D15=0,"",IF(B15<>"",B15,IFERROR(INDEX(反算辅助!$DC$2:$DC$13,ROW()-4),""))) | H15: =IF(ISNUMBER(G15),G15/(1+IF(G15<100000,0,1%)),"") | I15: =IF(ISNUMBER(G15),IF(H15<100000,0,H15*1%),"") | J15: =IF(ISNUMBER(G15),IF(H15<100000,0,I15*2.5%),"") | K15: =IF(ISNUMBER(G15),IF(H15<100000,0,I15*1.5%),"") | L15: =IF(ISNUMBER(G15),IF(H15<100000,0,I15*1%),"") | M15: =IF(ISNUMBER(G15),G15-I15,"") | N15: =IF(D15=0,"",AA15*80%-5000*E15-Z15) | O15: =IF(D15=0,"",IF(N15<=36000,3%,IF(N15<=144000,10%,IF(N15<=300000,20%,IF(N15<=420000,25%,IF(N15<=660000,30%,IF(N15<=960000,35%,45%))))))) | P15: =IF(D15=0,"",IF(N15<=36000,0,IF(N15<=144000,2520,IF(N15<=300000,16920,IF(N15<=420000,31920,IF(N15<=660000,52920,IF(N15<=960000,85920,181920))))))) | Q15: =IF(D15=0,"",MAX(0,N15*O15-P15-F15)) | R15: =IF(D15=0,"",I15+J15+K15+L15+Q15) | S15: =IF(D15=0,"",G15-R15) | T15: =IF(D15=0,"",F15+Q15) | U15: =IF(AND(C15<>"",B15=""),S15-C15,"") | V15: =IF(AND(D15=1,ISNUMBER(G15)=FALSE),"反算失败，请检查输入",IF(AND(B15<>"",C15<>""),"已按含税金额优先","")) | W15: =IF(ISNUMBER(G15),J15+K15+L15,"") | X15: =IF(D15=0,"",IF(D14=0,G15,X14+G15)) | Y15: =IF(D15=0,"",IF(D14=0,I15,Y14+I15)) | Z15: =IF(D15=0,"",IF(D14=0,W15,Z14+W15)) | AA15: =IF(D15=0,"",X15-Y15) | AB15: =IF(D15=0,"",IF(D14=0,0,AA14)) | AC15: =IF(D15=0,"",IF(D14=0,0,Z14))
A16: 12 | D16: =IF(OR(B16<>"",C16<>""),1,0) | E16: =IF(D16=0,0,IF(D15=0,1,E15+1)) | F16: =IF(D16=0,"",IF(D15=0,0,T15)) | G16: =IF(D16=0,"",IF(B16<>"",B16,IFERROR(INDEX(反算辅助!$DC$2:$DC$13,ROW()-4),""))) | H16: =IF(ISNUMBER(G16),G16/(1+IF(G16<100000,0,1%)),"") | I16: =IF(ISNUMBER(G16),IF(H16<100000,0,H16*1%),"") | J16: =IF(ISNUMBER(G16),IF(H16<100000,0,I16*2.5%),"") | K16: =IF(ISNUMBER(G16),IF(H16<100000,0,I16*1.5%),"") | L16: =IF(ISNUMBER(G16),IF(H16<100000,0,I16*1%),"") | M16: =IF(ISNUMBER(G16),G16-I16,"") | N16: =IF(D16=0,"",AA16*80%-5000*E16-Z16) | O16: =IF(D16=0,"",IF(N16<=36000,3%,IF(N16<=144000,10%,IF(N16<=300000,20%,IF(N16<=420000,25%,IF(N16<=660000,30%,IF(N16<=960000,35%,45%))))))) | P16: =IF(D16=0,"",IF(N16<=36000,0,IF(N16<=144000,2520,IF(N16<=300000,16920,IF(N16<=420000,31920,IF(N16<=660000,52920,IF(N16<=960000,85920,181920))))))) | Q16: =IF(D16=0,"",MAX(0,N16*O16-P16-F16)) | R16: =IF(D16=0,"",I16+J16+K16+L16+Q16) | S16: =IF(D16=0,"",G16-R16) | T16: =IF(D16=0,"",F16+Q16) | U16: =IF(AND(C16<>"",B16=""),S16-C16,"") | V16: =IF(AND(D16=1,ISNUMBER(G16)=FALSE),"反算失败，请检查输入",IF(AND(B16<>"",C16<>""),"已按含税金额优先","")) | W16: =IF(ISNUMBER(G16),J16+K16+L16,"") | X16: =IF(D16=0,"",IF(D15=0,G16,X15+G16)) | Y16: =IF(D16=0,"",IF(D15=0,I16,Y15+I16)) | Z16: =IF(D16=0,"",IF(D15=0,W16,Z15+W16)) | AA16: =IF(D16=0,"",X16-Y16) | AB16: =IF(D16=0,"",IF(D15=0,0,AA15)) | AC16: =IF(D16=0,"",IF(D15=0,0,Z15))

Sheet 反算辅助
A1: 月份 | B1: 目标实发 | C1: 是否有收入 | D1: 输入含税 | E1: 连续月数 | F1: 累计已预扣个税 | G1: 上月累计收入 | H1: 上月累计附加 | I1: K常数 | J1: 无增值税/PIT=0 | K1: 有增值税/PIT=0 | L1: 无增值税/3% | M1: 无增值税/10% | N1: 无增值税/20% | O1: 无增值税/25% | P1: 无增值税/30% | Q1: 无增值税/35% | R1: 无增值税/45% | S1: 有增值税/3% | T1: 有增值税/10% | U1: 有增值税/20% | V1: 有增值税/25% | W1: 有增值税/30% | X1: 有增值税/35% | Y1: 有增值税/45% | Z1: TC1 | AA1: TC2 | AB1: TC3 | AC1: TC4 | AD1: TC5 | AE1: TC6 | AF1: TC7 | AG1: TC8 | AH1: TC9 | AI1: TC10 | AJ1: TC11 | AK1: TC12 | AL1: TC13 | AM1: TC14 | AN1: TC15 | AO1: TC16 | AP1: PIT1 | AQ1: PIT2 | AR1: PIT3 | AS1: PIT4 | AT1: PIT5 | AU1: PIT6 | AV1: PIT7 | AW1: PIT8 | AX1: PIT9 | AY1: PIT10 | AZ1: PIT11 | BA1: PIT12 | BB1: PIT13 | BC1: PIT14 | BD1: PIT15 | BE1: PIT16 | BF1: NET1 | BG1: NET2 | BH1: NET3 | BI1: NET4 | BJ1: NET5 | BK1: NET6 | BL1: NET7 | BM1: NET8 | BN1: NET9 | BO1: NET10 | BP1: NET11 | BQ1: NET12 | BR1: NET13 | BS1: NET14 | BT1: NET15 | BU1: NET16 | BV1: ERR1 | BW1: ERR2 | BX1: ERR3 | BY1: ERR4 | BZ1: ERR5 | CA1: ERR6 | CB1: ERR7 | CC1: ERR8 | CD1: ERR9 | CE1: ERR10 | CF1: ERR11 | CG1: ERR12 | CH1: ERR13 | CI1: ERR14 | CJ1: ERR15 | CK1: ERR16 | CL1: VALID1 | CM1: VALID2 | CN1: VALID3 | CO1: VALID4 | CP1: VALID5 | CQ1: VALID6 | CR1: VALID7 | CS1: VALID8 | CT1: VALID9 | CU1: VALID10 | CV1: VALID11 | CW1: VALID12 | CX1: VALID13 | CY1: VALID14 | CZ1: VALID15 | DA1: VALID16 | DB1: 命中序号 | DC1: 反算含税 | DD1: 回算实发
A2: 1 | B2: ='月度计算'!C5 | C2: ='月度计算'!D5 | D2: ='月度计算'!B5 | E2: ='月度计算'!E5 | F2: ='月度计算'!F5 | G2: ='月度计算'!AB5 | H2: ='月度计算'!AC5 | I2: =IF(C2=0,"",G2*80%-5000*E2-H2) | J2: =IF(OR($C2=0,$B2="",$D2<>""),"",$B2/(1-(0))) | K2: =IF(OR($C2=0,$B2="",$D2<>""),"",$B2/(1-(21/2020))) | L2: =IF(OR($C2=0,$B2="",$D2<>""),"",($B2-0-$F2+$I2*0.03)/(1-(0)-(0.8)*0.03)) | M2: =IF(OR($C2=0,$B2="",$D2<>""),"",($B2-2520-$F2+$I2*0.1)/(1-(0)-(0.8)*0.1)) | N2: =IF(OR($C2=0,$B2="",$D2<>""),"",($B2-16920-$F2+$I2*0.2)/(1-(0)-(0.8)*0.2)) | O2: =IF(OR($C2=0,$B2="",$D2<>""),"",($B2-31920-$F2+$I2*0.25)/(1-(0)-(0.8)*0.25)) | P2: =IF(OR($C2=0,$B2="",$D2<>""),"",($B2-52920-$F2+$I2*0.3)/(1-(0)-(0.8)*0.3)) | Q2: =IF(OR($C2=0,$B2="",$D2<>""),"",($B2-85920-$F2+$I2*0.35)/(1-(0)-(0.8)*0.35)) | R2: =IF(OR($C2=0,$B2="",$D2<>""),"",($B2-181920-$F2+$I2*0.45)/(1-(0)-(0.8)*0.45)) | S2: =IF(OR($C2=0,$B2="",$D2<>""),"",($B2-0-$F2+$I2*0.03)/(1-(21/2020)-(1599/2020)*0.03)) | T2: =IF(OR($C2=0,$B2="",$D2<>""),"",($B2-2520-$F2+$I2*0.1)/(1-(21/2020)-(1599/2020)*0.1)) | U2: =IF(OR($C2=0,$B2="",$D2<>""),"",($B2-16920-$F2+$I2*0.2)/(1-(21/2020)-(1599/2020)*0.2)) | V2: =IF(OR($C2=0,$B2="",$D2<>""),"",($B2-31920-$F2+$I2*0.25)/(1-(21/2020)-(1599/2020)*0.25)) | W2: =IF(OR($C2=0,$B2="",$D2<>""),"",($B2-52920-$F2+$I2*0.3)/(1-(21/2020)-(1599/2020)*0.3)) | X2: =IF(OR($C2=0,$B2="",$D2<>""),"",($B2-85920-$F2+$I2*0.35)/(1-(21/2020)-(1599/2020)*0.35)) | Y2: =IF(OR($C2=0,$B2="",$D2<>""),"",($B2-181920-$F2+$I2*0.45)/(1-(21/2020)-(1599/2020)*0.45)) | Z2: =IF(J2="","",($G2+J2-(IF(J2/(1+IF(J2<100000,0,1%))<100000,0,J2/(1+IF(J2<100000,0,1%))*1%)))*80%-5000*$E2-($H2+(IF(J2/(1+IF(J2<100000,0,1%))<100000,0,J2/(1+IF(J2<100000,0,1%))*1%*5%)))) | AA2: =IF(K2="","",($G2+K2-(IF(K2/(1+IF(K2<100000,0,1%))<100000,0,K2/(1+IF(K2<100000,0,1%))*1%)))*80%-5000*$E2-($H2+(IF(K2/(1+IF(K2<100000,0,1%))<100000,0,K2/(1+IF(K2<100000,0,1%))*1%*5%)))) | AB2: =IF(L2="","",($G2+L2-(IF(L2/(1+IF(L2<100000,0,1%))<100000,0,L2/(1+IF(L2<100000,0,1%))*1%)))*80%-5000*$E2-($H2+(IF(L2/(1+IF(L2<100000,0,1%))<100000,0,L2/(1+IF(L2<100000,0,1%))*1%*5%)))) | AC2: =IF(M2="","",($G2+M2-(IF(M2/(1+IF(M2<100000,0,1%))<100000,0,M2/(1+IF(M2<100000,0,1%))*1%)))*80%-5000*$E2-($H2+(IF(M2/(1+IF(M2<100000,0,1%))<100000,0,M2/(1+IF(M2<100000,0,1%))*1%*5%)))) | AD2: =IF(N2="","",($G2+N2-(IF(N2/(1+IF(N2<100000,0,1%))<100000,0,N2/(1+IF(N2<100000,0,1%))*1%)))*80%-5000*$E2-($H2+(IF(N2/(1+IF(N2<100000,0,1%))<100000,0,N2/(1+IF(N2<100000,0,1%))*1%*5%)))) | AE2: =IF(O2="","",($G2+O2-(IF(O2/(1+IF(O2<100000,0,1%))<100000,0,O2/(1+IF(O2<100000,0,1%))*1%)))*80%-5000*$E2-($H2+(IF(O2/(1+IF(O2<100000,0,1%))<100000,0,O2/(1+IF(O2<100000,0,1%))*1%*5%)))) | AF2: =IF(P2="","",($G2+P2-(IF(P2/(1+IF(P2<100000,0,1%))<100000,0,P2/(1+IF(P2<100000,0,1%))*1%)))*80%-5000*$E2-($H2+(IF(P2/(1+IF(P2<100000,0,1%))<100000,0,P2/(1+IF(P2<100000,0,1%))*1%*5%)))) | AG2: =IF(Q2="","",($G2+Q2-(IF(Q2/(1+IF(Q2<100000,0,1%))<100000,0,Q2/(1+IF(Q2<100000,0,1%))*1%)))*80%-5000*$E2-($H2+(IF(Q2/(1+IF(Q2<100000,0,1%))<100000,0,Q2/(1+IF(Q2<100000,0,1%))*1%*5%)))) | ... AO2: =IF(Y2="","",($G2+Y2-(IF(Y2/(1+IF(Y2<100000,0,1%))<100000,0,Y2/(1+IF(Y2<100000,0,1%))*1%)))*80%-5000*$E2-($H2+(IF(Y2/(1+IF(Y2<100000,0,1%))<100000,0,Y2/(1+IF(Y2<100000,0,1%))*1%*5%)))) | AP2: =IF(Z2="","",MAX(0,Z2*IF(Z2<=36000,3%,IF(Z2<=144000,10%,IF(Z2<=300000,20%,IF(Z2<=420000,25%,IF(Z2<=660000,30%,IF(Z2<=960000,35%,45%))))))-IF(Z2<=36000,0,IF(Z2<=144000,2520,IF(Z2<=300000,16920,IF(Z2<=420000,31920,IF(Z2<=660000,52920,IF(Z2<=960000,85920,181920))))))-$F2)) | AQ2: =IF(AA2="","",MAX(0,AA2*IF(AA2<=36000,3%,IF(AA2<=144000,10%,IF(AA2<=300000,20%,IF(AA2<=420000,25%,IF(AA2<=660000,30%,IF(AA2<=960000,35%,45%))))))-IF(AA2<=36000,0,IF(AA2<=144000,2520,IF(AA2<=300000,16920,IF(AA2<=420000,31920,IF(AA2<=660000,52920,IF(AA2<=960000,85920,181920))))))-$F2)) | AR2: =IF(AB2="","",MAX(0,AB2*IF(AB2<=36000,3%,IF(AB2<=144000,10%,IF(AB2<=300000,20%,IF(AB2<=420000,25%,IF(AB2<=660000,30%,IF(AB2<=960000,35%,45%))))))-IF(AB2<=36000,0,IF(AB2<=144000,2520,IF(AB2<=300000,16920,IF(AB2<=420000,31920,IF(AB2<=660000,52920,IF(AB2<=960000,85920,181920))))))-$F2)) | AS2: =IF(AC2="","",MAX(0,AC2*IF(AC2<=36000,3%,IF(AC2<=144000,10%,IF(AC2<=300000,20%,IF(AC2<=420000,25%,IF(AC2<=660000,30%,IF(AC2<=960000,35%,45%))))))-IF(AC2<=36000,0,IF(AC2<=144000,2520,IF(AC2<=300000,16920,IF(AC2<=420000,31920,IF(AC2<=660000,52920,IF(AC2<=960000,85920,181920))))))-$F2)) | AT2: =IF(AD2="","",MAX(0,AD2*IF(AD2<=36000,3%,IF(AD2<=144000,10%,IF(AD2<=300000,20%,IF(AD2<=420000,25%,IF(AD2<=660000,30%,IF(AD2<=960000,35%,45%))))))-IF(AD2<=36000,0,IF(AD2<=144000,2520,IF(AD2<=300000,16920,IF(AD2<=420000,31920,IF(AD2<=660000,52920,IF(AD2<=960000,85920,181920))))))-$F2)) | AU2: =IF(AE2="","",MAX(0,AE2*IF(AE2<=36000,3%,IF(AE2<=144000,10%,IF(AE2<=300000,20%,IF(AE2<=420000,25%,IF(AE2<=660000,30%,IF(AE2<=960000,35%,45%))))))-IF(AE2<=36000,0,IF(AE2<=144000,2520,IF(AE2<=300000,16920,IF(AE2<=420000,31920,IF(AE2<=660000,52920,IF(AE2<=960000,85920,181920))))))-$F2)) | AV2: =IF(AF2="","",MAX(0,AF2*IF(AF2<=36000,3%,IF(AF2<=144000,10%,IF(AF2<=300000,20%,IF(AF2<=420000,25%,IF(AF2<=660000,30%,IF(AF2<=960000,35%,45%))))))-IF(AF2<=36000,0,IF(AF2<=144000,2520,IF(AF2<=300000,16920,IF(AF2<=420000,31920,IF(AF2<=660000,52920,IF(AF2<=960000,85920,181920))))))-$F2)) | AW2: =IF(AG2="","",MAX(0,AG2*IF(AG2<=36000,3%,IF(AG2<=144000,10%,IF(AG2<=300000,20%,IF(AG2<=420000,25%,IF(AG2<=660000,30%,IF(AG2<=960000,35%,45%))))))-IF(AG2<=36000,0,IF(AG2<=144000,2520,IF(AG2<=300000,16920,IF(AG2<=420000,31920,IF(AG2<=660000,52920,IF(AG2<=960000,85920,181920))))))-$F2)) | ... BE2: =IF(AO2="","",MAX(0,AO2*IF(AO2<=36000,3%,IF(AO2<=144000,10%,IF(AO2<=300000,20%,IF(AO2<=420000,25%,IF(AO2<=660000,30%,IF(AO2<=960000,35%,45%))))))-IF(AO2<=36000,0,IF(AO2<=144000,2520,IF(AO2<=300000,16920,IF(AO2<=420000,31920,IF(AO2<=660000,52920,IF(AO2<=960000,85920,181920))))))-$F2)) | BF2: =IF(J2="","",J2-(IF(J2/(1+IF(J2<100000,0,1%))<100000,0,J2/(1+IF(J2<100000,0,1%))*1%))-(IF(J2/(1+IF(J2<100000,0,1%))<100000,0,J2/(1+IF(J2<100000,0,1%))*1%*5%))-AP2) | BG2: =IF(K2="","",K2-(IF(K2/(1+IF(K2<100000,0,1%))<100000,0,K2/(1+IF(K2<100000,0,1%))*1%))-(IF(K2/(1+IF(K2<100000,0,1%))<100000,0,K2/(1+IF(K2<100000,0,1%))*1%*5%))-AQ2) | BH2: =IF(L2="","",L2-(IF(L2/(1+IF(L2<100000,0,1%))<100000,0,L2/(1+IF(L2<100000,0,1%))*1%))-(IF(L2/(1+IF(L2<100000,0,1%))<100000,0,L2/(1+IF(L2<100000,0,1%))*1%*5%))-AR2) | BI2: =IF(M2="","",M2-(IF(M2/(1+IF(M2<100000,0,1%))<100000,0,M2/(1+IF(M2<100000,0,1%))*1%))-(IF(M2/(1+IF(M2<100000,0,1%))<100000,0,M2/(1+IF(M2<100000,0,1%))*1%*5%))-AS2) | BJ2: =IF(N2="","",N2-(IF(N2/(1+IF(N2<100000,0,1%))<100000,0,N2/(1+IF(N2<100000,0,1%))*1%))-(IF(N2/(1+IF(N2<100000,0,1%))<100000,0,N2/(1+IF(N2<100000,0,1%))*1%*5%))-AT2) | BK2: =IF(O2="","",O2-(IF(O2/(1+IF(O2<100000,0,1%))<100000,0,O2/(1+IF(O2<100000,0,1%))*1%))-(IF(O2/(1+IF(O2<100000,0,1%))<100000,0,O2/(1+IF(O2<100000,0,1%))*1%*5%))-AU2) | BL2: =IF(P2="","",P2-(IF(P2/(1+IF(P2<100000,0,1%))<100000,0,P2/(1+IF(P2<100000,0,1%))*1%))-(IF(P2/(1+IF(P2<100000,0,1%))<100000,0,P2/(1+IF(P2<100000,0,1%))*1%*5%))-AV2) | BM2: =IF(Q2="","",Q2-(IF(Q2/(1+IF(Q2<100000,0,1%))<100000,0,Q2/(1+IF(Q2<100000,0,1%))*1%))-(IF(Q2/(1+IF(Q2<100000,0,1%))<100000,0,Q2/(1+IF(Q2<100000,0,1%))*1%*5%))-AW2) | ... BU2: =IF(Y2="","",Y2-(IF(Y2/(1+IF(Y2<100000,0,1%))<100000,0,Y2/(1+IF(Y2<100000,0,1%))*1%))-(IF(Y2/(1+IF(Y2<100000,0,1%))<100000,0,Y2/(1+IF(Y2<100000,0,1%))*1%*5%))-BE2) | BV2: =IF(BF2="","",ABS(BF2-$B2)) | BW2: =IF(BG2="","",ABS(BG2-$B2)) | BX2: =IF(BH2="","",ABS(BH2-$B2)) | BY2: =IF(BI2="","",ABS(BI2-$B2)) | BZ2: =IF(BJ2="","",ABS(BJ2-$B2)) | CA2: =IF(BK2="","",ABS(BK2-$B2)) | CB2: =IF(BL2="","",ABS(BL2-$B2)) | CC2: =IF(BM2="","",ABS(BM2-$B2)) | ... CK2: =IF(BU2="","",ABS(BU2-$B2)) | CL2: =IF(J2="","",AND(J2>0,J2<101000,BV2<0.05,AP2=0)) | CM2: =IF(K2="","",AND(K2>0,K2>=101000,BW2<0.05,AQ2=0)) | CN2: =IF(L2="","",AND(L2>0,L2<101000,BX2<0.05,AR2>0)) | CO2: =IF(M2="","",AND(M2>0,M2<101000,BY2<0.05,AS2>0)) | CP2: =IF(N2="","",AND(N2>0,N2<101000,BZ2<0.05,AT2>0)) | CQ2: =IF(O2="","",AND(O2>0,O2<101000,CA2<0.05,AU2>0)) | CR2: =IF(P2="","",AND(P2>0,P2<101000,CB2<0.05,AV2>0)) | CS2: =IF(Q2="","",AND(Q2>0,Q2<101000,CC2<0.05,AW2>0)) | CT2: =IF(R2="","",AND(R2>0,R2<101000,CD2<0.05,AX2>0)) | CU2: =IF(S2="","",AND(S2>0,S2>=101000,CE2<0.05,AY2>0)) | CV2: =IF(T2="","",AND(T2>0,T2>=101000,CF2<0.05,AZ2>0)) | CW2: =IF(U2="","",AND(U2>0,U2>=101000,CG2<0.05,BA2>0)) | CX2: =IF(V2="","",AND(V2>0,V2>=101000,CH2<0.05,BB2>0)) | CY2: =IF(W2="","",AND(W2>0,W2>=101000,CI2<0.05,BC2>0)) | CZ2: =IF(X2="","",AND(X2>0,X2>=101000,CJ2<0.05,BD2>0)) | DA2: =IF(Y2="","",AND(Y2>0,Y2>=101000,CK2<0.05,BE2>0)) | DB2: =IFERROR(MATCH(TRUE,CL2:DA2,0),"") | DC2: =IF(DB2="","",INDEX(J2:Y2,DB2)) | DD2: =IF(DB2="","",INDEX(BF2:BU2,DB2))
A3: 2 | B3: ='月度计算'!C6 | C3: ='月度计算'!D6 | D3: ='月度计算'!B6 | E3: ='月度计算'!E6 | F3: ='月度计算'!F6 | G3: ='月度计算'!AB6 | H3: ='月度计算'!AC6 | I3: =IF(C3=0,"",G3*80%-5000*E3-H3) | J3: =IF(OR($C3=0,$B3="",$D3<>""),"",$B3/(1-(0))) | K3: =IF(OR($C3=0,$B3="",$D3<>""),"",$B3/(1-(21/2020))) | L3: =IF(OR($C3=0,$B3="",$D3<>""),"",($B3-0-$F3+$I3*0.03)/(1-(0)-(0.8)*0.03)) | M3: =IF(OR($C3=0,$B3="",$D3<>""),"",($B3-2520-$F3+$I3*0.1)/(1-(0)-(0.8)*0.1)) | N3: =IF(OR($C3=0,$B3="",$D3<>""),"",($B3-16920-$F3+$I3*0.2)/(1-(0)-(0.8)*0.2)) | O3: =IF(OR($C3=0,$B3="",$D3<>""),"",($B3-31920-$F3+$I3*0.25)/(1-(0)-(0.8)*0.25)) | P3: =IF(OR($C3=0,$B3="",$D3<>""),"",($B3-52920-$F3+$I3*0.3)/(1-(0)-(0.8)*0.3)) | Q3: =IF(OR($C3=0,$B3="",$D3<>""),"",($B3-85920-$F3+$I3*0.35)/(1-(0)-(0.8)*0.35)) | R3: =IF(OR($C3=0,$B3="",$D3<>""),"",($B3-181920-$F3+$I3*0.45)/(1-(0)-(0.8)*0.45)) | S3: =IF(OR($C3=0,$B3="",$D3<>""),"",($B3-0-$F3+$I3*0.03)/(1-(21/2020)-(1599/2020)*0.03)) | T3: =IF(OR($C3=0,$B3="",$D3<>""),"",($B3-2520-$F3+$I3*0.1)/(1-(21/2020)-(1599/2020)*0.1)) | U3: =IF(OR($C3=0,$B3="",$D3<>""),"",($B3-16920-$F3+$I3*0.2)/(1-(21/2020)-(1599/2020)*0.2)) | V3: =IF(OR($C3=0,$B3="",$D3<>""),"",($B3-31920-$F3+$I3*0.25)/(1-(21/2020)-(1599/2020)*0.25)) | W3: =IF(OR($C3=0,$B3="",$D3<>""),"",($B3-52920-$F3+$I3*0.3)/(1-(21/2020)-(1599/2020)*0.3)) | X3: =IF(OR($C3=0,$B3="",$D3<>""),"",($B3-85920-$F3+$I3*0.35)/(1-(21/2020)-(1599/2020)*0.35)) | Y3: =IF(OR($C3=0,$B3="",$D3<>""),"",($B3-181920-$F3+$I3*0.45)/(1-(21/2020)-(1599/2020)*0.45)) | Z3: =IF(J3="","",($G3+J3-(IF(J3/(1+IF(J3<100000,0,1%))<100000,0,J3/(1+IF(J3<100000,0,1%))*1%)))*80%-5000*$E3-($H3+(IF(J3/(1+IF(J3<100000,0,1%))<100000,0,J3/(1+IF(J3<100000,0,1%))*1%*5%)))) | AA3: =IF(K3="","",($G3+K3-(IF(K3/(1+IF(K3<100000,0,1%))<100000,0,K3/(1+IF(K3<100000,0,1%))*1%)))*80%-5000*$E3-($H3+(IF(K3/(1+IF(K3<100000,0,1%))<100000,0,K3/(1+IF(K3<100000,0,1%))*1%*5%)))) | AB3: =IF(L3="","",($G3+L3-(IF(L3/(1+IF(L3<100000,0,1%))<100000,0,L3/(1+IF(L3<100000,0,1%))*1%)))*80%-5000*$E3-($H3+(IF(L3/(1+IF(L3<100000,0,1%))<100000,0,L3/(1+IF(L3<100000,0,1%))*1%*5%)))) | AC3: =IF(M3="","",($G3+M3-(IF(M3/(1+IF(M3<100000,0,1%))<100000,0,M3/(1+IF(M3<100000,0,1%))*1%)))*80%-5000*$E3-($H3+(IF(M3/(1+IF(M3<100000,0,1%))<100000,0,M3/(1+IF(M3<100000,0,1%))*1%*5%)))) | AD3: =IF(N3="","",($G3+N3-(IF(N3/(1+IF(N3<100000,0,1%))<100000,0,N3/(1+IF(N3<100000,0,1%))*1%)))*80%-5000*$E3-($H3+(IF(N3/(1+IF(N3<100000,0,1%))<100000,0,N3/(1+IF(N3<100000,0,1%))*1%*5%)))) | AE3: =IF(O3="","",($G3+O3-(IF(O3/(1+IF(O3<100000,0,1%))<100000,0,O3/(1+IF(O3<100000,0,1%))*1%)))*80%-5000*$E3-($H3+(IF(O3/(1+IF(O3<100000,0,1%))<100000,0,O3/(1+IF(O3<100000,0,1%))*1%*5%)))) | AF3: =IF(P3="","",($G3+P3-(IF(P3/(1+IF(P3<100000,0,1%))<100000,0,P3/(1+IF(P3<100000,0,1%))*1%)))*80%-5000*$E3-($H3+(IF(P3/(1+IF(P3<100000,0,1%))<100000,0,P3/(1+IF(P3<100000,0,1%))*1%*5%)))) | AG3: =IF(Q3="","",($G3+Q3-(IF(Q3/(1+IF(Q3<100000,0,1%))<100000,0,Q3/(1+IF(Q3<100000,0,1%))*1%)))*80%-5000*$E3-($H3+(IF(Q3/(1+IF(Q3<100000,0,1%))<100000,0,Q3/(1+IF(Q3<100000,0,1%))*1%*5%)))) | ... AO3: =IF(Y3="","",($G3+Y3-(IF(Y3/(1+IF(Y3<100000,0,1%))<100000,0,Y3/(1+IF(Y3<100000,0,1%))*1%)))*80%-5000*$E3-($H3+(IF(Y3/(1+IF(Y3<100000,0,1%))<100000,0,Y3/(1+IF(Y3<100000,0,1%))*1%*5%)))) | AP3: =IF(Z3="","",MAX(0,Z3*IF(Z3<=36000,3%,IF(Z3<=144000,10%,IF(Z3<=300000,20%,IF(Z3<=420000,25%,IF(Z3<=660000,30%,IF(Z3<=960000,35%,45%))))))-IF(Z3<=36000,0,IF(Z3<=144000,2520,IF(Z3<=300000,16920,IF(Z3<=420000,31920,IF(Z3<=660000,52920,IF(Z3<=960000,85920,181920))))))-$F3)) | AQ3: =IF(AA3="","",MAX(0,AA3*IF(AA3<=36000,3%,IF(AA3<=144000,10%,IF(AA3<=300000,20%,IF(AA3<=420000,25%,IF(AA3<=660000,30%,IF(AA3<=960000,35%,45%))))))-IF(AA3<=36000,0,IF(AA3<=144000,2520,IF(AA3<=300000,16920,IF(AA3<=420000,31920,IF(AA3<=660000,52920,IF(AA3<=960000,85920,181920))))))-$F3)) | AR3: =IF(AB3="","",MAX(0,AB3*IF(AB3<=36000,3%,IF(AB3<=144000,10%,IF(AB3<=300000,20%,IF(AB3<=420000,25%,IF(AB3<=660000,30%,IF(AB3<=960000,35%,45%))))))-IF(AB3<=36000,0,IF(AB3<=144000,2520,IF(AB3<=300000,16920,IF(AB3<=420000,31920,IF(AB3<=660000,52920,IF(AB3<=960000,85920,181920))))))-$F3)) | AS3: =IF(AC3="","",MAX(0,AC3*IF(AC3<=36000,3%,IF(AC3<=144000,10%,IF(AC3<=300000,20%,IF(AC3<=420000,25%,IF(AC3<=660000,30%,IF(AC3<=960000,35%,45%))))))-IF(AC3<=36000,0,IF(AC3<=144000,2520,IF(AC3<=300000,16920,IF(AC3<=420000,31920,IF(AC3<=660000,52920,IF(AC3<=960000,85920,181920))))))-$F3)) | AT3: =IF(AD3="","",MAX(0,AD3*IF(AD3<=36000,3%,IF(AD3<=144000,10%,IF(AD3<=300000,20%,IF(AD3<=420000,25%,IF(AD3<=660000,30%,IF(AD3<=960000,35%,45%))))))-IF(AD3<=36000,0,IF(AD3<=144000,2520,IF(AD3<=300000,16920,IF(AD3<=420000,31920,IF(AD3<=660000,52920,IF(AD3<=960000,85920,181920))))))-$F3)) | AU3: =IF(AE3="","",MAX(0,AE3*IF(AE3<=36000,3%,IF(AE3<=144000,10%,IF(AE3<=300000,20%,IF(AE3<=420000,25%,IF(AE3<=660000,30%,IF(AE3<=960000,35%,45%))))))-IF(AE3<=36000,0,IF(AE3<=144000,2520,IF(AE3<=300000,16920,IF(AE3<=420000,31920,IF(AE3<=660000,52920,IF(AE3<=960000,85920,181920))))))-$F3)) | AV3: =IF(AF3="","",MAX(0,AF3*IF(AF3<=36000,3%,IF(AF3<=144000,10%,IF(AF3<=300000,20%,IF(AF3<=420000,25%,IF(AF3<=660000,30%,IF(AF3<=960000,35%,45%))))))-IF(AF3<=36000,0,IF(AF3<=144000,2520,IF(AF3<=300000,16920,IF(AF3<=420000,31920,IF(AF3<=660000,52920,IF(AF3<=960000,85920,181920))))))-$F3)) | AW3: =IF(AG3="","",MAX(0,AG3*IF(AG3<=36000,3%,IF(AG3<=144000,10%,IF(AG3<=300000,20%,IF(AG3<=420000,25%,IF(AG3<=660000,30%,IF(AG3<=960000,35%,45%))))))-IF(AG3<=36000,0,IF(AG3<=144000,2520,IF(AG3<=300000,16920,IF(AG3<=420000,31920,IF(AG3<=660000,52920,IF(AG3<=960000,85920,181920))))))-$F3)) | ... BE3: =IF(AO3="","",MAX(0,AO3*IF(AO3<=36000,3%,IF(AO3<=144000,10%,IF(AO3<=300000,20%,IF(AO3<=420000,25%,IF(AO3<=660000,30%,IF(AO3<=960000,35%,45%))))))-IF(AO3<=36000,0,IF(AO3<=144000,2520,IF(AO3<=300000,16920,IF(AO3<=420000,31920,IF(AO3<=660000,52920,IF(AO3<=960000,85920,181920))))))-$F3)) | BF3: =IF(J3="","",J3-(IF(J3/(1+IF(J3<100000,0,1%))<100000,0,J3/(1+IF(J3<100000,0,1%))*1%))-(IF(J3/(1+IF(J3<100000,0,1%))<100000,0,J3/(1+IF(J3<100000,0,1%))*1%*5%))-AP3) | BG3: =IF(K3="","",K3-(IF(K3/(1+IF(K3<100000,0,1%))<100000,0,K3/(1+IF(K3<100000,0,1%))*1%))-(IF(K3/(1+IF(K3<100000,0,1%))<100000,0,K3/(1+IF(K3<100000,0,1%))*1%*5%))-AQ3) | BH3: =IF(L3="","",L3-(IF(L3/(1+IF(L3<100000,0,1%))<100000,0,L3/(1+IF(L3<100000,0,1%))*1%))-(IF(L3/(1+IF(L3<100000,0,1%))<100000,0,L3/(1+IF(L3<100000,0,1%))*1%*5%))-AR3) | BI3: =IF(M3="","",M3-(IF(M3/(1+IF(M3<100000,0,1%))<100000,0,M3/(1+IF(M3<100000,0,1%))*1%))-(IF(M3/(1+IF(M3<100000,0,1%))<100000,0,M3/(1+IF(M3<100000,0,1%))*1%*5%))-AS3) | BJ3: =IF(N3="","",N3-(IF(N3/(1+IF(N3<100000,0,1%))<100000,0,N3/(1+IF(N3<100000,0,1%))*1%))-(IF(N3/(1+IF(N3<100000,0,1%))<100000,0,N3/(1+IF(N3<100000,0,1%))*1%*5%))-AT3) | BK3: =IF(O3="","",O3-(IF(O3/(1+IF(O3<100000,0,1%))<100000,0,O3/(1+IF(O3<100000,0,1%))*1%))-(IF(O3/(1+IF(O3<100000,0,1%))<100000,0,O3/(1+IF(O3<100000,0,1%))*1%*5%))-AU3) | BL3: =IF(P3="","",P3-(IF(P3/(1+IF(P3<100000,0,1%))<100000,0,P3/(1+IF(P3<100000,0,1%))*1%))-(IF(P3/(1+IF(P3<100000,0,1%))<100000,0,P3/(1+IF(P3<100000,0,1%))*1%*5%))-AV3) | BM3: =IF(Q3="","",Q3-(IF(Q3/(1+IF(Q3<100000,0,1%))<100000,0,Q3/(1+IF(Q3<100000,0,1%))*1%))-(IF(Q3/(1+IF(Q3<100000,0,1%))<100000,0,Q3/(1+IF(Q3<100000,0,1%))*1%*5%))-AW3) | ... BU3: =IF(Y3="","",Y3-(IF(Y3/(1+IF(Y3<100000,0,1%))<100000,0,Y3/(1+IF(Y3<100000,0,1%))*1%))-(IF(Y3/(1+IF(Y3<100000,0,1%))<100000,0,Y3/(1+IF(Y3<100000,0,1%))*1%*5%))-BE3) | BV3: =IF(BF3="","",ABS(BF3-$B3)) | BW3: =IF(BG3="","",ABS(BG3-$B3)) | BX3: =IF(BH3="","",ABS(BH3-$B3)) | BY3: =IF(BI3="","",ABS(BI3-$B3)) | BZ3: =IF(BJ3="","",ABS(BJ3-$B3)) | CA3: =IF(BK3="","",ABS(BK3-$B3)) | CB3: =IF(BL3="","",ABS(BL3-$B3)) | CC3: =IF(BM3="","",ABS(BM3-$B3)) | ... CK3: =IF(BU3="","",ABS(BU3-$B3)) | CL3: =IF(J3="","",AND(J3>0,J3<101000,BV3<0.05,AP3=0)) | CM3: =IF(K3="","",AND(K3>0,K3>=101000,BW3<0.05,AQ3=0)) | CN3: =IF(L3="","",AND(L3>0,L3<101000,BX3<0.05,AR3>0)) | CO3: =IF(M3="","",AND(M3>0,M3<101000,BY3<0.05,AS3>0)) | CP3: =IF(N3="","",AND(N3>0,N3<101000,BZ3<0.05,AT3>0)) | CQ3: =IF(O3="","",AND(O3>0,O3<101000,CA3<0.05,AU3>0)) | CR3: =IF(P3="","",AND(P3>0,P3<101000,CB3<0.05,AV3>0)) | CS3: =IF(Q3="","",AND(Q3>0,Q3<101000,CC3<0.05,AW3>0)) | CT3: =IF(R3="","",AND(R3>0,R3<101000,CD3<0.05,AX3>0)) | CU3: =IF(S3="","",AND(S3>0,S3>=101000,CE3<0.05,AY3>0)) | CV3: =IF(T3="","",AND(T3>0,T3>=101000,CF3<0.05,AZ3>0)) | CW3: =IF(U3="","",AND(U3>0,U3>=101000,CG3<0.05,BA3>0)) | CX3: =IF(V3="","",AND(V3>0,V3>=101000,CH3<0.05,BB3>0)) | CY3: =IF(W3="","",AND(W3>0,W3>=101000,CI3<0.05,BC3>0)) | CZ3: =IF(X3="","",AND(X3>0,X3>=101000,CJ3<0.05,BD3>0)) | DA3: =IF(Y3="","",AND(Y3>0,Y3>=101000,CK3<0.05,BE3>0)) | DB3: =IFERROR(MATCH(TRUE,CL3:DA3,0),"") | DC3: =IF(DB3="","",INDEX(J3:Y3,DB3)) | DD3: =IF(DB3="","",INDEX(BF3:BU3,DB3))
A4: 3 | B4: ='月度计算'!C7 | C4: ='月度计算'!D7 | D4: ='月度计算'!B7 | E4: ='月度计算'!E7 | F4: ='月度计算'!F7 | G4: ='月度计算'!AB7 | H4: ='月度计算'!AC7 | I4: =IF(C4=0,"",G4*80%-5000*E4-H4) | J4: =IF(OR($C4=0,$B4="",$D4<>""),"",$B4/(1-(0))) | K4: =IF(OR($C4=0,$B4="",$D4<>""),"",$B4/(1-(21/2020))) | L4: =IF(OR($C4=0,$B4="",$D4<>""),"",($B4-0-$F4+$I4*0.03)/(1-(0)-(0.8)*0.03)) | M4: =IF(OR($C4=0,$B4="",$D4<>""),"",($B4-2520-$F4+$I4*0.1)/(1-(0)-(0.8)*0.1)) | N4: =IF(OR($C4=0,$B4="",$D4<>""),"",($B4-16920-$F4+$I4*0.2)/(1-(0)-(0.8)*0.2)) | O4: =IF(OR($C4=0,$B4="",$D4<>""),"",($B4-31920-$F4+$I4*0.25)/(1-(0)-(0.8)*0.25)) | P4: =IF(OR($C4=0,$B4="",$D4<>""),"",($B4-52920-$F4+$I4*0.3)/(1-(0)-(0.8)*0.3)) | Q4: =IF(OR($C4=0,$B4="",$D4<>""),"",($B4-85920-$F4+$I4*0.35)/(1-(0)-(0.8)*0.35)) | R4: =IF(OR($C4=0,$B4="",$D4<>""),"",($B4-181920-$F4+$I4*0.45)/(1-(0)-(0.8)*0.45)) | S4: =IF(OR($C4=0,$B4="",$D4<>""),"",($B4-0-$F4+$I4*0.03)/(1-(21/2020)-(1599/2020)*0.03)) | T4: =IF(OR($C4=0,$B4="",$D4<>""),"",($B4-2520-$F4+$I4*0.1)/(1-(21/2020)-(1599/2020)*0.1)) | U4: =IF(OR($C4=0,$B4="",$D4<>""),"",($B4-16920-$F4+$I4*0.2)/(1-(21/2020)-(1599/2020)*0.2)) | V4: =IF(OR($C4=0,$B4="",$D4<>""),"",($B4-31920-$F4+$I4*0.25)/(1-(21/2020)-(1599/2020)*0.25)) | W4: =IF(OR($C4=0,$B4="",$D4<>""),"",($B4-52920-$F4+$I4*0.3)/(1-(21/2020)-(1599/2020)*0.3)) | X4: =IF(OR($C4=0,$B4="",$D4<>""),"",($B4-85920-$F4+$I4*0.35)/(1-(21/2020)-(1599/2020)*0.35)) | Y4: =IF(OR($C4=0,$B4="",$D4<>""),"",($B4-181920-$F4+$I4*0.45)/(1-(21/2020)-(1599/2020)*0.45)) | Z4: =IF(J4="","",($G4+J4-(IF(J4/(1+IF(J4<100000,0,1%))<100000,0,J4/(1+IF(J4<100000,0,1%))*1%)))*80%-5000*$E4-($H4+(IF(J4/(1+IF(J4<100000,0,1%))<100000,0,J4/(1+IF(J4<100000,0,1%))*1%*5%)))) | AA4: =IF(K4="","",($G4+K4-(IF(K4/(1+IF(K4<100000,0,1%))<100000,0,K4/(1+IF(K4<100000,0,1%))*1%)))*80%-5000*$E4-($H4+(IF(K4/(1+IF(K4<100000,0,1%))<100000,0,K4/(1+IF(K4<100000,0,1%))*1%*5%)))) | AB4: =IF(L4="","",($G4+L4-(IF(L4/(1+IF(L4<100000,0,1%))<100000,0,L4/(1+IF(L4<100000,0,1%))*1%)))*80%-5000*$E4-($H4+(IF(L4/(1+IF(L4<100000,0,1%))<100000,0,L4/(1+IF(L4<100000,0,1%))*1%*5%)))) | AC4: =IF(M4="","",($G4+M4-(IF(M4/(1+IF(M4<100000,0,1%))<100000,0,M4/(1+IF(M4<100000,0,1%))*1%)))*80%-5000*$E4-($H4+(IF(M4/(1+IF(M4<100000,0,1%))<100000,0,M4/(1+IF(M4<100000,0,1%))*1%*5%)))) | AD4: =IF(N4="","",($G4+N4-(IF(N4/(1+IF(N4<100000,0,1%))<100000,0,N4/(1+IF(N4<100000,0,1%))*1%)))*80%-5000*$E4-($H4+(IF(N4/(1+IF(N4<100000,0,1%))<100000,0,N4/(1+IF(N4<100000,0,1%))*1%*5%)))) | AE4: =IF(O4="","",($G4+O4-(IF(O4/(1+IF(O4<100000,0,1%))<100000,0,O4/(1+IF(O4<100000,0,1%))*1%)))*80%-5000*$E4-($H4+(IF(O4/(1+IF(O4<100000,0,1%))<100000,0,O4/(1+IF(O4<100000,0,1%))*1%*5%)))) | AF4: =IF(P4="","",($G4+P4-(IF(P4/(1+IF(P4<100000,0,1%))<100000,0,P4/(1+IF(P4<100000,0,1%))*1%)))*80%-5000*$E4-($H4+(IF(P4/(1+IF(P4<100000,0,1%))<100000,0,P4/(1+IF(P4<100000,0,1%))*1%*5%)))) | AG4: =IF(Q4="","",($G4+Q4-(IF(Q4/(1+IF(Q4<100000,0,1%))<100000,0,Q4/(1+IF(Q4<100000,0,1%))*1%)))*80%-5000*$E4-($H4+(IF(Q4/(1+IF(Q4<100000,0,1%))<100000,0,Q4/(1+IF(Q4<100000,0,1%))*1%*5%)))) | ... AO4: =IF(Y4="","",($G4+Y4-(IF(Y4/(1+IF(Y4<100000,0,1%))<100000,0,Y4/(1+IF(Y4<100000,0,1%))*1%)))*80%-5000*$E4-($H4+(IF(Y4/(1+IF(Y4<100000,0,1%))<100000,0,Y4/(1+IF(Y4<100000,0,1%))*1%*5%)))) | AP4: =IF(Z4="","",MAX(0,Z4*IF(Z4<=36000,3%,IF(Z4<=144000,10%,IF(Z4<=300000,20%,IF(Z4<=420000,25%,IF(Z4<=660000,30%,IF(Z4<=960000,35%,45%))))))-IF(Z4<=36000,0,IF(Z4<=144000,2520,IF(Z4<=300000,16920,IF(Z4<=420000,31920,IF(Z4<=660000,52920,IF(Z4<=960000,85920,181920))))))-$F4)) | AQ4: =IF(AA4="","",MAX(0,AA4*IF(AA4<=36000,3%,IF(AA4<=144000,10%,IF(AA4<=300000,20%,IF(AA4<=420000,25%,IF(AA4<=660000,30%,IF(AA4<=960000,35%,45%))))))-IF(AA4<=36000,0,IF(AA4<=144000,2520,IF(AA4<=300000,16920,IF(AA4<=420000,31920,IF(AA4<=660000,52920,IF(AA4<=960000,85920,181920))))))-$F4)) | AR4: =IF(AB4="","",MAX(0,AB4*IF(AB4<=36000,3%,IF(AB4<=144000,10%,IF(AB4<=300000,20%,IF(AB4<=420000,25%,IF(AB4<=660000,30%,IF(AB4<=960000,35%,45%))))))-IF(AB4<=36000,0,IF(AB4<=144000,2520,IF(AB4<=300000,16920,IF(AB4<=420000,31920,IF(AB4<=660000,52920,IF(AB4<=960000,85920,181920))))))-$F4)) | AS4: =IF(AC4="","",MAX(0,AC4*IF(AC4<=36000,3%,IF(AC4<=144000,10%,IF(AC4<=300000,20%,IF(AC4<=420000,25%,IF(AC4<=660000,30%,IF(AC4<=960000,35%,45%))))))-IF(AC4<=36000,0,IF(AC4<=144000,2520,IF(AC4<=300000,16920,IF(AC4<=420000,31920,IF(AC4<=660000,52920,IF(AC4<=960000,85920,181920))))))-$F4)) | AT4: =IF(AD4="","",MAX(0,AD4*IF(AD4<=36000,3%,IF(AD4<=144000,10%,IF(AD4<=300000,20%,IF(AD4<=420000,25%,IF(AD4<=660000,30%,IF(AD4<=960000,35%,45%))))))-IF(AD4<=36000,0,IF(AD4<=144000,2520,IF(AD4<=300000,16920,IF(AD4<=420000,31920,IF(AD4<=660000,52920,IF(AD4<=960000,85920,181920))))))-$F4)) | AU4: =IF(AE4="","",MAX(0,AE4*IF(AE4<=36000,3%,IF(AE4<=144000,10%,IF(AE4<=300000,20%,IF(AE4<=420000,25%,IF(AE4<=660000,30%,IF(AE4<=960000,35%,45%))))))-IF(AE4<=36000,0,IF(AE4<=144000,2520,IF(AE4<=300000,16920,IF(AE4<=420000,31920,IF(AE4<=660000,52920,IF(AE4<=960000,85920,181920))))))-$F4)) | AV4: =IF(AF4="","",MAX(0,AF4*IF(AF4<=36000,3%,IF(AF4<=144000,10%,IF(AF4<=300000,20%,IF(AF4<=420000,25%,IF(AF4<=660000,30%,IF(AF4<=960000,35%,45%))))))-IF(AF4<=36000,0,IF(AF4<=144000,2520,IF(AF4<=300000,16920,IF(AF4<=420000,31920,IF(AF4<=660000,52920,IF(AF4<=960000,85920,181920))))))-$F4)) | AW4: =IF(AG4="","",MAX(0,AG4*IF(AG4<=36000,3%,IF(AG4<=144000,10%,IF(AG4<=300000,20%,IF(AG4<=420000,25%,IF(AG4<=660000,30%,IF(AG4<=960000,35%,45%))))))-IF(AG4<=36000,0,IF(AG4<=144000,2520,IF(AG4<=300000,16920,IF(AG4<=420000,31920,IF(AG4<=660000,52920,IF(AG4<=960000,85920,181920))))))-$F4)) | ... BE4: =IF(AO4="","",MAX(0,AO4*IF(AO4<=36000,3%,IF(AO4<=144000,10%,IF(AO4<=300000,20%,IF(AO4<=420000,25%,IF(AO4<=660000,30%,IF(AO4<=960000,35%,45%))))))-IF(AO4<=36000,0,IF(AO4<=144000,2520,IF(AO4<=300000,16920,IF(AO4<=420000,31920,IF(AO4<=660000,52920,IF(AO4<=960000,85920,181920))))))-$F4)) | BF4: =IF(J4="","",J4-(IF(J4/(1+IF(J4<100000,0,1%))<100000,0,J4/(1+IF(J4<100000,0,1%))*1%))-(IF(J4/(1+IF(J4<100000,0,1%))<100000,0,J4/(1+IF(J4<100000,0,1%))*1%*5%))-AP4) | BG4: =IF(K4="","",K4-(IF(K4/(1+IF(K4<100000,0,1%))<100000,0,K4/(1+IF(K4<100000,0,1%))*1%))-(IF(K4/(1+IF(K4<100000,0,1%))<100000,0,K4/(1+IF(K4<100000,0,1%))*1%*5%))-AQ4) | BH4: =IF(L4="","",L4-(IF(L4/(1+IF(L4<100000,0,1%))<100000,0,L4/(1+IF(L4<100000,0,1%))*1%))-(IF(L4/(1+IF(L4<100000,0,1%))<100000,0,L4/(1+IF(L4<100000,0,1%))*1%*5%))-AR4) | BI4: =IF(M4="","",M4-(IF(M4/(1+IF(M4<100000,0,1%))<100000,0,M4/(1+IF(M4<100000,0,1%))*1%))-(IF(M4/(1+IF(M4<100000,0,1%))<100000,0,M4/(1+IF(M4<100000,0,1%))*1%*5%))-AS4) | BJ4: =IF(N4="","",N4-(IF(N4/(1+IF(N4<100000,0,1%))<100000,0,N4/(1+IF(N4<100000,0,1%))*1%))-(IF(N4/(1+IF(N4<100000,0,1%))<100000,0,N4/(1+IF(N4<100000,0,1%))*1%*5%))-AT4) | BK4: =IF(O4="","",O4-(IF(O4/(1+IF(O4<100000,0,1%))<100000,0,O4/(1+IF(O4<100000,0,1%))*1%))-(IF(O4/(1+IF(O4<100000,0,1%))<100000,0,O4/(1+IF(O4<100000,0,1%))*1%*5%))-AU4) | BL4: =IF(P4="","",P4-(IF(P4/(1+IF(P4<100000,0,1%))<100000,0,P4/(1+IF(P4<100000,0,1%))*1%))-(IF(P4/(1+IF(P4<100000,0,1%))<100000,0,P4/(1+IF(P4<100000,0,1%))*1%*5%))-AV4) | BM4: =IF(Q4="","",Q4-(IF(Q4/(1+IF(Q4<100000,0,1%))<100000,0,Q4/(1+IF(Q4<100000,0,1%))*1%))-(IF(Q4/(1+IF(Q4<100000,0,1%))<100000,0,Q4/(1+IF(Q4<100000,0,1%))*1%*5%))-AW4) | ... BU4: =IF(Y4="","",Y4-(IF(Y4/(1+IF(Y4<100000,0,1%))<100000,0,Y4/(1+IF(Y4<100000,0,1%))*1%))-(IF(Y4/(1+IF(Y4<100000,0,1%))<100000,0,Y4/(1+IF(Y4<100000,0,1%))*1%*5%))-BE4) | BV4: =IF(BF4="","",ABS(BF4-$B4)) | BW4: =IF(BG4="","",ABS(BG4-$B4)) | BX4: =IF(BH4="","",ABS(BH4-$B4)) | BY4: =IF(BI4="","",ABS(BI4-$B4)) | BZ4: =IF(BJ4="","",ABS(BJ4-$B4)) | CA4: =IF(BK4="","",ABS(BK4-$B4)) | CB4: =IF(BL4="","",ABS(BL4-$B4)) | CC4: =IF(BM4="","",ABS(BM4-$B4)) | ... CK4: =IF(BU4="","",ABS(BU4-$B4)) | CL4: =IF(J4="","",AND(J4>0,J4<101000,BV4<0.05,AP4=0)) | CM4: =IF(K4="","",AND(K4>0,K4>=101000,BW4<0.05,AQ4=0)) | CN4: =IF(L4="","",AND(L4>0,L4<101000,BX4<0.05,AR4>0)) | CO4: =IF(M4="","",AND(M4>0,M4<101000,BY4<0.05,AS4>0)) | CP4: =IF(N4="","",AND(N4>0,N4<101000,BZ4<0.05,AT4>0)) | CQ4: =IF(O4="","",AND(O4>0,O4<101000,CA4<0.05,AU4>0)) | CR4: =IF(P4="","",AND(P4>0,P4<101000,CB4<0.05,AV4>0)) | CS4: =IF(Q4="","",AND(Q4>0,Q4<101000,CC4<0.05,AW4>0)) | CT4: =IF(R4="","",AND(R4>0,R4<101000,CD4<0.05,AX4>0)) | CU4: =IF(S4="","",AND(S4>0,S4>=101000,CE4<0.05,AY4>0)) | CV4: =IF(T4="","",AND(T4>0,T4>=101000,CF4<0.05,AZ4>0)) | CW4: =IF(U4="","",AND(U4>0,U4>=101000,CG4<0.05,BA4>0)) | CX4: =IF(V4="","",AND(V4>0,V4>=101000,CH4<0.05,BB4>0)) | CY4: =IF(W4="","",AND(W4>0,W4>=101000,CI4<0.05,BC4>0)) | CZ4: =IF(X4="","",AND(X4>0,X4>=101000,CJ4<0.05,BD4>0)) | DA4: =IF(Y4="","",AND(Y4>0,Y4>=101000,CK4<0.05,BE4>0)) | DB4: =IFERROR(MATCH(TRUE,CL4:DA4,0),"") | DC4: =IF(DB4="","",INDEX(J4:Y4,DB4)) | DD4: =IF(DB4="","",INDEX(BF4:BU4,DB4))
A5: 4 | B5: ='月度计算'!C8 | C5: ='月度计算'!D8 | D5: ='月度计算'!B8 | E5: ='月度计算'!E8 | F5: ='月度计算'!F8 | G5: ='月度计算'!AB8 | H5: ='月度计算'!AC8 | I5: =IF(C5=0,"",G5*80%-5000*E5-H5) | J5: =IF(OR($C5=0,$B5="",$D5<>""),"",$B5/(1-(0))) | K5: =IF(OR($C5=0,$B5="",$D5<>""),"",$B5/(1-(21/2020))) | L5: =IF(OR($C5=0,$B5="",$D5<>""),"",($B5-0-$F5+$I5*0.03)/(1-(0)-(0.8)*0.03)) | M5: =IF(OR($C5=0,$B5="",$D5<>""),"",($B5-2520-$F5+$I5*0.1)/(1-(0)-(0.8)*0.1)) | N5: =IF(OR($C5=0,$B5="",$D5<>""),"",($B5-16920-$F5+$I5*0.2)/(1-(0)-(0.8)*0.2)) | O5: =IF(OR($C5=0,$B5="",$D5<>""),"",($B5-31920-$F5+$I5*0.25)/(1-(0)-(0.8)*0.25)) | P5: =IF(OR($C5=0,$B5="",$D5<>""),"",($B5-52920-$F5+$I5*0.3)/(1-(0)-(0.8)*0.3)) | Q5: =IF(OR($C5=0,$B5="",$D5<>""),"",($B5-85920-$F5+$I5*0.35)/(1-(0)-(0.8)*0.35)) | R5: =IF(OR($C5=0,$B5="",$D5<>""),"",($B5-181920-$F5+$I5*0.45)/(1-(0)-(0.8)*0.45)) | S5: =IF(OR($C5=0,$B5="",$D5<>""),"",($B5-0-$F5+$I5*0.03)/(1-(21/2020)-(1599/2020)*0.03)) | T5: =IF(OR($C5=0,$B5="",$D5<>""),"",($B5-2520-$F5+$I5*0.1)/(1-(21/2020)-(1599/2020)*0.1)) | U5: =IF(OR($C5=0,$B5="",$D5<>""),"",($B5-16920-$F5+$I5*0.2)/(1-(21/2020)-(1599/2020)*0.2)) | V5: =IF(OR($C5=0,$B5="",$D5<>""),"",($B5-31920-$F5+$I5*0.25)/(1-(21/2020)-(1599/2020)*0.25)) | W5: =IF(OR($C5=0,$B5="",$D5<>""),"",($B5-52920-$F5+$I5*0.3)/(1-(21/2020)-(1599/2020)*0.3)) | X5: =IF(OR($C5=0,$B5="",$D5<>""),"",($B5-85920-$F5+$I5*0.35)/(1-(21/2020)-(1599/2020)*0.35)) | Y5: =IF(OR($C5=0,$B5="",$D5<>""),"",($B5-181920-$F5+$I5*0.45)/(1-(21/2020)-(1599/2020)*0.45)) | Z5: =IF(J5="","",($G5+J5-(IF(J5/(1+IF(J5<100000,0,1%))<100000,0,J5/(1+IF(J5<100000,0,1%))*1%)))*80%-5000*$E5-($H5+(IF(J5/(1+IF(J5<100000,0,1%))<100000,0,J5/(1+IF(J5<100000,0,1%))*1%*5%)))) | AA5: =IF(K5="","",($G5+K5-(IF(K5/(1+IF(K5<100000,0,1%))<100000,0,K5/(1+IF(K5<100000,0,1%))*1%)))*80%-5000*$E5-($H5+(IF(K5/(1+IF(K5<100000,0,1%))<100000,0,K5/(1+IF(K5<100000,0,1%))*1%*5%)))) | AB5: =IF(L5="","",($G5+L5-(IF(L5/(1+IF(L5<100000,0,1%))<100000,0,L5/(1+IF(L5<100000,0,1%))*1%)))*80%-5000*$E5-($H5+(IF(L5/(1+IF(L5<100000,0,1%))<100000,0,L5/(1+IF(L5<100000,0,1%))*1%*5%)))) | AC5: =IF(M5="","",($G5+M5-(IF(M5/(1+IF(M5<100000,0,1%))<100000,0,M5/(1+IF(M5<100000,0,1%))*1%)))*80%-5000*$E5-($H5+(IF(M5/(1+IF(M5<100000,0,1%))<100000,0,M5/(1+IF(M5<100000,0,1%))*1%*5%)))) | AD5: =IF(N5="","",($G5+N5-(IF(N5/(1+IF(N5<100000,0,1%))<100000,0,N5/(1+IF(N5<100000,0,1%))*1%)))*80%-5000*$E5-($H5+(IF(N5/(1+IF(N5<100000,0,1%))<100000,0,N5/(1+IF(N5<100000,0,1%))*1%*5%)))) | AE5: =IF(O5="","",($G5+O5-(IF(O5/(1+IF(O5<100000,0,1%))<100000,0,O5/(1+IF(O5<100000,0,1%))*1%)))*80%-5000*$E5-($H5+(IF(O5/(1+IF(O5<100000,0,1%))<100000,0,O5/(1+IF(O5<100000,0,1%))*1%*5%)))) | AF5: =IF(P5="","",($G5+P5-(IF(P5/(1+IF(P5<100000,0,1%))<100000,0,P5/(1+IF(P5<100000,0,1%))*1%)))*80%-5000*$E5-($H5+(IF(P5/(1+IF(P5<100000,0,1%))<100000,0,P5/(1+IF(P5<100000,0,1%))*1%*5%)))) | AG5: =IF(Q5="","",($G5+Q5-(IF(Q5/(1+IF(Q5<100000,0,1%))<100000,0,Q5/(1+IF(Q5<100000,0,1%))*1%)))*80%-5000*$E5-($H5+(IF(Q5/(1+IF(Q5<100000,0,1%))<100000,0,Q5/(1+IF(Q5<100000,0,1%))*1%*5%)))) | ... AO5: =IF(Y5="","",($G5+Y5-(IF(Y5/(1+IF(Y5<100000,0,1%))<100000,0,Y5/(1+IF(Y5<100000,0,1%))*1%)))*80%-5000*$E5-($H5+(IF(Y5/(1+IF(Y5<100000,0,1%))<100000,0,Y5/(1+IF(Y5<100000,0,1%))*1%*5%)))) | AP5: =IF(Z5="","",MAX(0,Z5*IF(Z5<=36000,3%,IF(Z5<=144000,10%,IF(Z5<=300000,20%,IF(Z5<=420000,25%,IF(Z5<=660000,30%,IF(Z5<=960000,35%,45%))))))-IF(Z5<=36000,0,IF(Z5<=144000,2520,IF(Z5<=300000,16920,IF(Z5<=420000,31920,IF(Z5<=660000,52920,IF(Z5<=960000,85920,181920))))))-$F5)) | AQ5: =IF(AA5="","",MAX(0,AA5*IF(AA5<=36000,3%,IF(AA5<=144000,10%,IF(AA5<=300000,20%,IF(AA5<=420000,25%,IF(AA5<=660000,30%,IF(AA5<=960000,35%,45%))))))-IF(AA5<=36000,0,IF(AA5<=144000,2520,IF(AA5<=300000,16920,IF(AA5<=420000,31920,IF(AA5<=660000,52920,IF(AA5<=960000,85920,181920))))))-$F5)) | AR5: =IF(AB5="","",MAX(0,AB5*IF(AB5<=36000,3%,IF(AB5<=144000,10%,IF(AB5<=300000,20%,IF(AB5<=420000,25%,IF(AB5<=660000,30%,IF(AB5<=960000,35%,45%))))))-IF(AB5<=36000,0,IF(AB5<=144000,2520,IF(AB5<=300000,16920,IF(AB5<=420000,31920,IF(AB5<=660000,52920,IF(AB5<=960000,85920,181920))))))-$F5)) | AS5: =IF(AC5="","",MAX(0,AC5*IF(AC5<=36000,3%,IF(AC5<=144000,10%,IF(AC5<=300000,20%,IF(AC5<=420000,25%,IF(AC5<=660000,30%,IF(AC5<=960000,35%,45%))))))-IF(AC5<=36000,0,IF(AC5<=144000,2520,IF(AC5<=300000,16920,IF(AC5<=420000,31920,IF(AC5<=660000,52920,IF(AC5<=960000,85920,181920))))))-$F5)) | AT5: =IF(AD5="","",MAX(0,AD5*IF(AD5<=36000,3%,IF(AD5<=144000,10%,IF(AD5<=300000,20%,IF(AD5<=420000,25%,IF(AD5<=660000,30%,IF(AD5<=960000,35%,45%))))))-IF(AD5<=36000,0,IF(AD5<=144000,2520,IF(AD5<=300000,16920,IF(AD5<=420000,31920,IF(AD5<=660000,52920,IF(AD5<=960000,85920,181920))))))-$F5)) | AU5: =IF(AE5="","",MAX(0,AE5*IF(AE5<=36000,3%,IF(AE5<=144000,10%,IF(AE5<=300000,20%,IF(AE5<=420000,25%,IF(AE5<=660000,30%,IF(AE5<=960000,35%,45%))))))-IF(AE5<=36000,0,IF(AE5<=144000,2520,IF(AE5<=300000,16920,IF(AE5<=420000,31920,IF(AE5<=660000,52920,IF(AE5<=960000,85920,181920))))))-$F5)) | AV5: =IF(AF5="","",MAX(0,AF5*IF(AF5<=36000,3%,IF(AF5<=144000,10%,IF(AF5<=300000,20%,IF(AF5<=420000,25%,IF(AF5<=660000,30%,IF(AF5<=960000,35%,45%))))))-IF(AF5<=36000,0,IF(AF5<=144000,2520,IF(AF5<=300000,16920,IF(AF5<=420000,31920,IF(AF5<=660000,52920,IF(AF5<=960000,85920,181920))))))-$F5)) | AW5: =IF(AG5="","",MAX(0,AG5*IF(AG5<=36000,3%,IF(AG5<=144000,10%,IF(AG5<=300000,20%,IF(AG5<=420000,25%,IF(AG5<=660000,30%,IF(AG5<=960000,35%,45%))))))-IF(AG5<=36000,0,IF(AG5<=144000,2520,IF(AG5<=300000,16920,IF(AG5<=420000,31920,IF(AG5<=660000,52920,IF(AG5<=960000,85920,181920))))))-$F5)) | ... BE5: =IF(AO5="","",MAX(0,AO5*IF(AO5<=36000,3%,IF(AO5<=144000,10%,IF(AO5<=300000,20%,IF(AO5<=420000,25%,IF(AO5<=660000,30%,IF(AO5<=960000,35%,45%))))))-IF(AO5<=36000,0,IF(AO5<=144000,2520,IF(AO5<=300000,16920,IF(AO5<=420000,31920,IF(AO5<=660000,52920,IF(AO5<=960000,85920,181920))))))-$F5)) | BF5: =IF(J5="","",J5-(IF(J5/(1+IF(J5<100000,0,1%))<100000,0,J5/(1+IF(J5<100000,0,1%))*1%))-(IF(J5/(1+IF(J5<100000,0,1%))<100000,0,J5/(1+IF(J5<100000,0,1%))*1%*5%))-AP5) | BG5: =IF(K5="","",K5-(IF(K5/(1+IF(K5<100000,0,1%))<100000,0,K5/(1+IF(K5<100000,0,1%))*1%))-(IF(K5/(1+IF(K5<100000,0,1%))<100000,0,K5/(1+IF(K5<100000,0,1%))*1%*5%))-AQ5) | BH5: =IF(L5="","",L5-(IF(L5/(1+IF(L5<100000,0,1%))<100000,0,L5/(1+IF(L5<100000,0,1%))*1%))-(IF(L5/(1+IF(L5<100000,0,1%))<100000,0,L5/(1+IF(L5<100000,0,1%))*1%*5%))-AR5) | BI5: =IF(M5="","",M5-(IF(M5/(1+IF(M5<100000,0,1%))<100000,0,M5/(1+IF(M5<100000,0,1%))*1%))-(IF(M5/(1+IF(M5<100000,0,1%))<100000,0,M5/(1+IF(M5<100000,0,1%))*1%*5%))-AS5) | BJ5: =IF(N5="","",N5-(IF(N5/(1+IF(N5<100000,0,1%))<100000,0,N5/(1+IF(N5<100000,0,1%))*1%))-(IF(N5/(1+IF(N5<100000,0,1%))<100000,0,N5/(1+IF(N5<100000,0,1%))*1%*5%))-AT5) | BK5: =IF(O5="","",O5-(IF(O5/(1+IF(O5<100000,0,1%))<100000,0,O5/(1+IF(O5<100000,0,1%))*1%))-(IF(O5/(1+IF(O5<100000,0,1%))<100000,0,O5/(1+IF(O5<100000,0,1%))*1%*5%))-AU5) | BL5: =IF(P5="","",P5-(IF(P5/(1+IF(P5<100000,0,1%))<100000,0,P5/(1+IF(P5<100000,0,1%))*1%))-(IF(P5/(1+IF(P5<100000,0,1%))<100000,0,P5/(1+IF(P5<100000,0,1%))*1%*5%))-AV5) | BM5: =IF(Q5="","",Q5-(IF(Q5/(1+IF(Q5<100000,0,1%))<100000,0,Q5/(1+IF(Q5<100000,0,1%))*1%))-(IF(Q5/(1+IF(Q5<100000,0,1%))<100000,0,Q5/(1+IF(Q5<100000,0,1%))*1%*5%))-AW5) | ... BU5: =IF(Y5="","",Y5-(IF(Y5/(1+IF(Y5<100000,0,1%))<100000,0,Y5/(1+IF(Y5<100000,0,1%))*1%))-(IF(Y5/(1+IF(Y5<100000,0,1%))<100000,0,Y5/(1+IF(Y5<100000,0,1%))*1%*5%))-BE5) | BV5: =IF(BF5="","",ABS(BF5-$B5)) | BW5: =IF(BG5="","",ABS(BG5-$B5)) | BX5: =IF(BH5="","",ABS(BH5-$B5)) | BY5: =IF(BI5="","",ABS(BI5-$B5)) | BZ5: =IF(BJ5="","",ABS(BJ5-$B5)) | CA5: =IF(BK5="","",ABS(BK5-$B5)) | CB5: =IF(BL5="","",ABS(BL5-$B5)) | CC5: =IF(BM5="","",ABS(BM5-$B5)) | ... CK5: =IF(BU5="","",ABS(BU5-$B5)) | CL5: =IF(J5="","",AND(J5>0,J5<101000,BV5<0.05,AP5=0)) | CM5: =IF(K5="","",AND(K5>0,K5>=101000,BW5<0.05,AQ5=0)) | CN5: =IF(L5="","",AND(L5>0,L5<101000,BX5<0.05,AR5>0)) | CO5: =IF(M5="","",AND(M5>0,M5<101000,BY5<0.05,AS5>0)) | CP5: =IF(N5="","",AND(N5>0,N5<101000,BZ5<0.05,AT5>0)) | CQ5: =IF(O5="","",AND(O5>0,O5<101000,CA5<0.05,AU5>0)) | CR5: =IF(P5="","",AND(P5>0,P5<101000,CB5<0.05,AV5>0)) | CS5: =IF(Q5="","",AND(Q5>0,Q5<101000,CC5<0.05,AW5>0)) | CT5: =IF(R5="","",AND(R5>0,R5<101000,CD5<0.05,AX5>0)) | CU5: =IF(S5="","",AND(S5>0,S5>=101000,CE5<0.05,AY5>0)) | CV5: =IF(T5="","",AND(T5>0,T5>=101000,CF5<0.05,AZ5>0)) | CW5: =IF(U5="","",AND(U5>0,U5>=101000,CG5<0.05,BA5>0)) | CX5: =IF(V5="","",AND(V5>0,V5>=101000,CH5<0.05,BB5>0)) | CY5: =IF(W5="","",AND(W5>0,W5>=101000,CI5<0.05,BC5>0)) | CZ5: =IF(X5="","",AND(X5>0,X5>=101000,CJ5<0.05,BD5>0)) | DA5: =IF(Y5="","",AND(Y5>0,Y5>=101000,CK5<0.05,BE5>0)) | DB5: =IFERROR(MATCH(TRUE,CL5:DA5,0),"") | DC5: =IF(DB5="","",INDEX(J5:Y5,DB5)) | DD5: =IF(DB5="","",INDEX(BF5:BU5,DB5))
